<mujoco model="niryo_one">
    <worldbody>
        <body name="base" pos="0 0 0">
            <geom type="box" size="0.05 0.05 0.05" rgba="1 0 0 1"/>
            <joint name="joint_1" type="hinge" axis="0 0 1" limited="true" range="-175 175"/>
            <body name="shoulder" pos="0 0 0.103">
                <geom type="cylinder" size="0.04 0.1" rgba="0 1 0 1"/>
                <joint name="joint_2" type="hinge" axis="0 1 0" pos="0 0 0.080" limited="true" range="-90 36.5"/>
                <body name="arm" pos="0 0 0.080">
                    <geom type="cylinder" size="0.03 0.210" rgba="0 0 1 1"/>
                    <joint name="joint_3" type="hinge" axis="1 0 0" pos="0.210 0 0" limited="true" range="-80 80"/>
                    <body name="elbow" pos="0.210 0 0">
                        <geom type="cylinder" size="0.02 0.15" rgba="1 1 0 1"/>
                        <joint name="joint_4" type="hinge" axis="0 1 0" pos="0.0415 0.030 0" limited="true" range="-175 175"/>
                        <body name="forearm" pos="0.0415 0.030 0">
                            <geom type="cylinder" size="0.02 0.180" rgba="1 0 1 1"/>
                            <joint name="joint_5" type="hinge" axis="1 0 0" pos="0 0 0.180" limited="true" range="-100 110"/>
                            <body name="wrist" pos="0 0 0.180">
                                <geom type="cylinder" size="0.02 0.1" rgba="0 1 1 1"/>
                                <joint name="joint_6" type="hinge" axis="0 1 0" pos="0.0164 -0.0055 0" limited="true" range="-147.6 147.6"/>
                                <body name="hand" pos="0.0164 -0.0055 0">
                                    <geom type="box" size="0.025 0.025 0.025" rgba="0.5 0.5 0.5 1"/>
                                    <!-- Add additional components or end-effector here -->
                                </body>
                            </body>
                        </body>
                    </body>
                </body>
            </body>
        </body>
    </worldbody>
</mujoco>
