<?xml version="1.0" ?>
<!-- =================================================================================== -->
<!-- |    This document was autogenerated by xacro from v2/without_mesh_niryo_one.urdf.xacro | -->
<!-- |    EDITING THIS FILE BY HAND IS NOT RECOMMENDED                                 | -->
<!-- =================================================================================== -->
<!--
    without_mesh_niryo_one.urdf.xacro
    Copyright (C) 2017 Niryo
    All rights reserved.

    This program is free software: you can redistribute it and/or modify
    it under the terms of the GNU General Public License as published by
    the Free Software Foundation, either version 3 of the License, or
    (at your option) any later version.

    This program is distributed in the hope that it will be useful,
    but WITHOUT ANY WARRANTY; without even the implied warranty of
    MERCHANTABILITY or FITNESS FOR A PARTICULAR PURPOSE.  See the
    GNU General Public License for more details.

    You should have received a copy of the GNU General Public License
    along with this program.  If not, see <http://www.gnu.org/licenses/>.
-->
<robot xmlns:xacro="http://www.ros.org/wiki/xacro" name="niryo_one">
  <!-- Properties -->
  <!-- Links -->
  <link name="world"/>
  <link name="base_link">
	</link>
  <link name="shoulder_link">
	</link>
  <link name="arm_link">
	</link>
  <link name="elbow_link">
	</link>
  <link name="forearm_link">
	</link>
  <link name="wrist_link">
	</link>
  <link name="hand_link">
	</link>
  <link name="tool_link">
	</link>
  <!--Joints -->
  <joint name="joint_world" type="fixed">
    <parent link="world"/>
    <child link="base_link"/>
    <origin xyz="0 0 0" rpy="0 0 0"/>
  </joint>
  <joint name="joint_1" type="revolute">
    <parent link="base_link"/>
    <child link="shoulder_link"/>
    <origin xyz="0 0 0.103" rpy="0 0 0"/>
    <axis xyz="0 0 1"/>
    <limit effort="1" velocity="1.0" lower="-3.05433" upper="3.05433"/>
  </joint>
  <joint name="joint_2" type="revolute">
    <parent link="shoulder_link"/>
    <child link="arm_link"/>
    <origin xyz="0 0 0.08" rpy="1.570796326795 -1.570796326795 0"/>
    <limit effort="1" velocity="1.0" lower="-1.5708" upper="0.640187"/>
    <axis xyz="0 0 1"/>
  </joint>
  <joint name="joint_3" type="revolute">
    <parent link="arm_link"/>
    <child link="elbow_link"/>
    <origin xyz="0.21 0.0 0" rpy="0 0 -1.570796326795"/>
    <limit effort="1" velocity="1.0" lower="-1.397485" upper="${PI/2}"/>
    <axis xyz="0 0 1"/>
  </joint>
  <joint name="joint_4" type="revolute">
    <parent link="elbow_link"/>
    <child link="forearm_link"/>
    <origin xyz="0.0415 0.03 0" rpy="0 1.570796326795 0"/>
    <limit effort="1" velocity="1.0" lower="-3.05433" upper="3.05433"/>
    <axis xyz="0 0 1"/>
  </joint>
  <joint name="joint_5" type="revolute">
    <parent link="forearm_link"/>
    <child link="wrist_link"/>
    <origin xyz="0 0 0.18" rpy="0 -1.570796326795 0"/>
    <limit effort="1" velocity="1.0" lower="-1.74533" upper="1.91986"/>
    <axis xyz="0 0 1"/>
  </joint>
  <joint name="joint_6" type="revolute">
    <parent link="wrist_link"/>
    <child link="hand_link"/>
    <origin xyz="0.0164 -0.0055 0" rpy="0 1.570796326795 0"/>
    <limit effort="1" velocity="1.0" lower="-2.57436" upper="2.57436"/>
    <axis xyz="0 0 1"/>
  </joint>
  <joint name="hand_tool_joint" type="fixed">
    <parent link="hand_link"/>
    <child link="tool_link"/>
    <origin xyz="0 0 0.0073" rpy="-1.570796326795 -1.570796326795 0"/>
  </joint>
</robot>
