<mujoco model="robot_arm_niryo">
  <compiler angle="radian"/>
  <asset>
    <mesh name="base_mesh" file="/home/xz2723/mujoco-ur5-model/niryo_one/meshes/v2/stl/base_link.stl"/>
    <mesh name="shoulder_mesh" file="/home/xz2723/mujoco-ur5-model/niryo_one/meshes/v2/stl/shoulder_link.stl"/>
    <mesh name="arm_mesh" file="/home/xz2723/mujoco-ur5-model/niryo_one/meshes/v2/stl/arm_link.stl"/>
    <mesh name="elbow_mesh" file="/home/xz2723/mujoco-ur5-model/niryo_one/meshes/v2/stl/elbow_link.stl"/>
    <mesh name="forearm_mesh" file="/home/xz2723/mujoco-ur5-model/niryo_one/meshes/v2/stl/forearm_link.stl"/>
    <mesh name="wrist_mesh" file="/home/xz2723/mujoco-ur5-model/niryo_one/meshes/v2/stl/wrist_link.stl"/>
    <mesh name="hand_mesh" file="/home/xz2723/mujoco-ur5-model/niryo_one/meshes/v2/stl/hand_link.stl"/>
  </asset>
  <worldbody>
    <body name="base">
      <joint name="joint_1" pos="0 0 0" axis="0 0 1" range="-3.05433 3.05433"/>
      <geom type="mesh" rgba="1 0 0 1" mesh="base_mesh"/>
      <body name="shoulder" pos="0 0 0.103">
        <joint name="joint_2" pos="0 0 0.08" axis="0 1 0" range="-1.5708 0.637045"/>
        <geom type="mesh" rgba="0 1 0 1" mesh="shoulder_mesh"/>
        <body name="arm" pos="0 0.08 0">
          <joint name="joint_3" pos="0.21 0 0" axis="1 0 0" range="-1.39626 1.39626"/>
          <geom type="mesh" rgba="0 0 1 1" mesh="arm_mesh"/>
          <body name="elbow" pos="0.21 0 0">
            <joint name="joint_4" pos="0.0415 0.03 0" axis="0 1 0" range="-3.05433 3.05433"/>
            <geom type="mesh" rgba="1 1 0 1" mesh="elbow_mesh"/>
            <body name="forearm" pos="0.0415 0.03 0">
              <joint name="joint_5" pos="0 0 0.18" axis="1 0 0" range="-1.74533 1.91986"/>
              <geom type="mesh" rgba="1 0 1 1" mesh="forearm_mesh"/>
              <body name="wrist" pos="0 0 0.18">
                <joint name="joint_6" pos="0.0164 -0.0055 0" axis="0 1 0" range="-2.57611 2.57611"/>
                <geom type="mesh" rgba="0 1 1 1" mesh="wrist_mesh"/>
                <body name="hand" pos="0.0164 -0.0055 0">
                  <geom type="mesh" mesh="hand_mesh"/>
                </body>
              </body>
            </body>
          </body>
        </body>
      </body>
    </body>
  </worldbody>
</mujoco>
