<?xml version="1.0"?>

<!--
    without_mesh_niryo_one.urdf
    Copyright (C) 2017 Niryo
    All rights reserved.

    This program is free software: you can redistribute it and/or modify
    it under the terms of the GNU General Public License as published by
    the Free Software Foundation, either version 3 of the License, or
    (at your option) any later version.

    This program is distributed in the hope that it will be useful,
    but WITHOUT ANY WARRANTY; without even the implied warranty of
    MERCHANTABILITY or FITNESS FOR A PARTICULAR PURPOSE.  See the
    GNU General Public License for more details.

    You should have received a copy of the GNU General Public License
    along with this program.  If not, see <http://www.gnu.org/licenses/>.
-->

<robot name="niryo_one">
	
    <!-- Links -->

    <link name="world"/>

    <!-- load the stl file for each link component -->
    <link name="base_link" />
        <visual>
            <geometry>
                <mesh filename="package://niryo_one/meshes/v2/stl/base_link.stl"/>
            </geometry>
        </visual>
        <collision>
            <geometry>
                <mesh filename="package://niryo_one/meshes/v2/stl/base_link.stl"/>
            </geometry>
        </collision>
    </link>

    <link name="shoulder_link">
        <visual>
            <geometry>
                <mesh filename="package://niryo_one/meshes/v2/stl/shoulder_link.stl"/>
            </geometry>
        </visual>
        <collision>
            <geometry>
                <mesh filename="package://niryo_one/meshes/v2/stl/shoulder_link.stl"/>
            </geometry>
        </collision>
    </link>

    <link name="arm_link">
        <visual>
            <geometry>
                <mesh filename="package://niryo_one/meshes/v2/stl/arm_link.stl"/>
            </geometry>
        </visual>
        <collision>
            <geometry>
                <mesh filename="package://niryo_one/meshes/v2/stl/arm_link.stl"/>
            </geometry>
        </collision>
    </link>

    <link name="elbow_link"/>
        <visual>
            <geometry>
                <mesh filename="package://niryo_one/meshes/v2/stl/elbow_link.stl"/>
            </geometry>
        </visual>
        <collision>
            <geometry>
                <mesh filename="package://niryo_one/meshes/v2/stl/elbow_link.stl"/>
            </geometry>
        </collision>
    </link>

    <link name="forearm_link"/>
        <visual>
            <geometry>
                <mesh filename="package://niryo_one/meshes/v2/stl/forearm_link.stl"/>
            </geometry>
        </visual>
        <collision>
            <geometry>
                <mesh filename="package://niryo_one/meshes/v2/stl/forearm_link.stl"/>
            </geometry>
        </collision>
    </link>

    <link name="wrist_link"/>
        <visual>
            <geometry>
                <mesh filename="package://niryo_one/meshes/v2/stl/wrist_link.stl"/>
            </geometry>
        </visual>
        <collision>
            <geometry>
                <mesh filename="package://niryo_one/meshes/v2/stl/wrist_link.stl"/>
            </geometry>
        </collision>
    </link>

    <link name="hand_link"/>
        <visual>
            <geometry>
                <mesh filename="package://niryo_one/meshes/v2/stl/hand_link.stl"/>
            </geometry>
        </visual>
        <collision>
            <geometry>
                <mesh filename="package://niryo_one/meshes/v2/stl/hand_link.stl"/>
            </geometry>
        </collision>
    </link>

    <link name="tool_link"/>
        <visual>
            <geometry>
                <mesh filename="package://niryo_one/meshes/v2/stl/tool_link.stl"/>
            </geometry>
        </visual>
        <collision>
            <geometry>
                <mesh filename="package://niryo_one/meshes/v2/stl/tool_link.stl"/>
            </geometry>
        </collision>
    </link>

    <!-- Joints -->

    <joint name="joint_world" type="fixed">
        <parent link="world"/>
        <child link="base_link"/>
        <origin xyz="0 0 0" rpy="0 0 0"/>
    </joint>

    <joint name="joint_1" type="revolute">
        <parent link="base_link"/>
        <child link="shoulder_link"/>
        <origin xyz="0 0 0.103" rpy="0 0 0"/>
        <axis xyz="0 0 1"/>
        <limit effort="1" velocity="1.0" lower="-3.05433" upper="3.05433"/>
    </joint>

    <joint name="joint_2" type="revolute">
        <parent link="shoulder_link"/>
        <child link="arm_link"/>
        <origin xyz="0 0 0.08" rpy="1.57079632679 -1.57079632679 0"/>
        <axis xyz="0 0 1"/>
        <limit effort="1" velocity="1.0" lower="-1.57080" upper="0.640187"/>
    </joint>

    <joint name="joint_3" type="revolute">
        <parent link="arm_link"/>
        <child link="elbow_link"/>
        <origin xyz="0.21 0.0 0" rpy="0 0 -1.57079632679"/>
        <axis xyz="0 0 1"/>
        <limit effort="1" velocity="1.0" lower="-1.397485" upper="1.57079632679"/>
    </joint>

    <joint name="joint_4" type="revolute">
        <parent link="elbow_link"/>
        <child link="forearm_link"/>
        <origin xyz="0.0415 0.03 0" rpy="0 1.57079632679 0"/>
        <axis xyz="0 0 1"/>
        <limit effort="1" velocity="1.0" lower="-3.05433" upper="3.05433"/>
    </joint>

    <joint name="joint_5" type="revolute">
        <parent link="forearm_link"/>
        <child link="wrist_link"/>
        <origin xyz="0 0 0.18" rpy="0 -1.57079632679 0"/>
        <axis xyz="0 0 1"/>
        <limit effort="1" velocity="1.0" lower="-1.74533" upper="1.91986"/>
    </joint>

    <joint name="joint_6" type="revolute">
        <parent link="wrist_link"/>
        <child link="hand_link"/>
        <origin xyz="0.0164 -0.0055 0" rpy="0 1.57079632679 0"/>
        <axis xyz="0 0 1"/>
        <limit effort="1" velocity="1.0" lower="-2.57436" upper="2.57436"/>
    </joint>

    <joint name="hand_tool_joint" type="fixed">
        <parent link="hand_link"/>
        <child link="tool_link"/>
        <origin xyz="0 0 0.0073" rpy="-1.57079632679 -1.57079632679 0"/>
    </joint>

</robot>