<?xml version="1.0"?>

<!--
    without_mesh_niryo_one.urdf
    Copyright (C) 2017 Niryo
    All rights reserved.

    This program is free software: you can redistribute it and/or modify
    it under the terms of the GNU General Public License as published by
    the Free Software Foundation, either version 3 of the License, or
    (at your option) any later version.

    This program is distributed in the hope that it will be useful,
    but WITHOUT ANY WARRANTY; without even the implied warranty of
    MERCHANTABILITY or FITNESS FOR A PARTICULAR PURPOSE.  See the
    GNU General Public License for more details.

    You should have received a copy of the GNU General Public License
    along with this program.  If not, see <http://www.gnu.org/licenses/>.
-->

<robot name="niryo_one">
	
    <!-- Links -->

    <link name="world"/>


    <!-- load the stl file for each link component -->
    <link name="base_link" />
        <visual>
            <geometry>
                <mesh filename="/niryo_one/meshes/v2/stl/base_link.stl"/>
            </geometry>
        </visual>
        <collision>
            <geometry>
                <mesh filename="/niryo_one/meshes/v2/stl/base_link.stl"/>
            </geometry>
        </collision>
    </link>

    <link name="shoulder_link">
        <visual>
            <geometry>
                <mesh filename="/niryo_one/meshes/v2/stl/shoulder_link.stl"/>
            </geometry>
        </visual>
        <collision>
            <geometry>
                <mesh filename="/niryo_one/meshes/v2/stl/shoulder_link.stl"/>
            </geometry>
        </collision>
    </link>

    <!-- Joints -->

    <joint name="joint_world" type="fixed">
        <parent link="world"/>
        <child link="base_link"/>
        <origin xyz="0 0 0" rpy="0 0 0"/>
    </joint>

    <joint name="joint_1" type="revolute">
        <parent link="base_link"/>
        <child link="shoulder_link"/>
        <origin xyz="0 0 0.103" rpy="0 0 0"/>
        <axis xyz="0 0 1"/>
        <limit effort="1" velocity="1.0" lower="-3.05433" upper="3.05433"/>
    </joint>

</robot>